Workbook

Sheet 00 시작하기
A1: J-5 수기 검산 워크북
A2: 코드가 낸 지수를 사람이 원자료부터 손으로 다시 계산해 대조한다 · 룰북 §14 · §18.4
A4: ■ 이 문서가 하는 일
A5: 코드가 계산한 값을 사람이 독립적으로 다시 계산합니다. 두 값이 같으면 구현이 규칙대로 작동한다는 증거가 됩니다.
A6: 다르면 어느 쪽이 틀렸는지 찾습니다. 어느 쪽이든 알아내는 것이 목적입니다.
A8: ■ 왜 필요한가
A9: 이미 코드로 독립 재산출을 해서 10개 항목이 일치했습니다. 그러나 그것은 코드가 코드를 검증한 것입니다.
A10: 두 구현이 같은 규칙을 같이 잘못 이해했다면 둘 다 같은 값을 냅니다. 사람이 손으로 한 번 따라가야 그 경우가 걸러집니다.
A12: ■ 반드시 지킬 것 — 답을 먼저 보지 않습니다
A13: 이 파일에는 코드가 낸 값이 하나도 들어 있지 않습니다. 일부러 뺐습니다.
A14: 답을 옆에 두고 채우면 무의식적으로 맞춰 쓰게 되어(확증편향) 검산이 성립하지 않습니다.
A15: 코드값은 J5_코드값_봉인.xlsx 에 따로 있습니다. 노란 칸을 전부 채우고 저장한 다음에 여십시오.
... A18: 색 범례
A19: 색 | B19: 뜻 | C19: 다루는 법
B20: 주어진 자료 | C20: 원자료입니다. 고치지 마십시오.
B21: 계산 칸 | C21: 직접 채웁니다. 엑셀 수식을 써도 됩니다.
B22: 최종 답 칸 | C22: 그 시트의 결론입니다. 대조표로 옮깁니다.
B23: 주의 | C23: 틀리기 쉬운 지점입니다. 읽고 진행하십시오.
A25: ■ 엑셀 수식을 써도 되나요
A26: 됩니다. 금지되는 것은 우리 프로젝트의 파이썬 코드를 돌리는 것입니다.
A27: 주어진 원자료에서 엑셀로 평균·정렬·보간을 하는 것은 독립적인 재계산이므로 검산에 해당합니다.
A29: 검산 기준 — 이 워크북이 무엇을 대상으로 하는지
A30: 항목 | B30: 값 | C30: 근거
A31: 유니버스 | B31: Seed 18 제한 파일럿 (A안) | C31: 회의 결정 2026-07-28
A32: 검산 회차 | B32: 2026-06-30 | C32: 자료마감일 2026-06-23
A33: 대상 산출물 | B33: data/pilot_run/output_f1 | C33: F-1 반영본
A34: 기업행사 | B34: 010120 액면분할 5:1 | C34: DART 20260205800571
A35: 조정 경계일 | B35: 2026-04-13 (신주권상장일) | C35: 효력발생일 2026-04-10 아님
A36: 지수 기준일 / 기준값 | B36: 2026-04-01 / 1,000 | C36: D-08
A38: 적용 규칙 — 2026-07-30 의결분 (파일럿 범위 한정)
A39: 항목 | B39: 의결 규칙 | C39: 범위·유보
A40: 환율 적용시점 | B40: 평가일 당일 ECOS — 지수·미국 BM 동일 적용 | C40: 계열코드 공식성 PROVISIONAL
A41: 산출일 | B41: COMMON_OPEN_DAYS_PILOT (한·미 공통 개장일) | C41: 합집합·가격이월은 후속 적용시험
A42: 연결 방식 | B42: CHAIN_REBASE_PILOT (연결계수) | C42: 이번 구간 미발동 — 정확성 실증 아님
A43: 기업행사 | B43: 액면가 기준 5:1 · 경계일 신주권상장일 | C43: 010120 개별 사건 판정 · 일반화 보류
A45: ■ 의결됐다고 검산이 필요 없어지는 것은 아닙니다 — 확인할 것이 바뀝니다.
A46: 의결 전: 룰북에서 규칙을 직접 도출해 보십시오.
A47: 의결 후: 의결 규칙을 적용하되, 그 규칙이 룰북에서 실제로 도출되는지 확인하십시오.
A48: 도출되지 않으면 그것이 발견사항입니다. 의결됐다는 이유로 넘기지 마십시오.
A49: 환율 항목은 QA 보고(당일 환율만 공표 지수를 재현함)가 의결 근거의 일부였습니다.
...

Sheet 02 자료마감일
A1: 자료마감일 — 선정일 이전 제5거래일
A2: 룰북 §5.2 · D-13 ⑧ · 축은 한·미 공통 개장일
A4: ■ 규칙
A5: 선정일 당일은 세지 않습니다. 선정일 바로 앞 개장일이 1거래일 전입니다.
A6: 한국과 미국이 모두 열린 날만 셉니다. 한쪽만 열린 날은 건너뜁니다.
A7: 값: 2026-06-23 근거: 결정로그 323행 D-13 ⑧ — "선정일 이전 제5거래일, 한·미 공통 개장일 기준 역산" "이전"이 선정일을 제외하므로 6/29부터 1,2,3,4,5 를 세어 6/23. 한계: 조문이 기산점(선정일을 0으로 볼지)을 명시하지 않았다. "이전"이라는 전치사로 추론했다. 조문 자체가 "정식 확정은 #30 적용시험 후"로 잠정 표기돼 있다. 제안: 데이터사전에 "기산점 = 선정일 당일 제외" 를 명문화할 것. 또는 조문을 "선정일 직전 거래일을 제1거래일로 하여 역산한 제5거래일" 로 정정.
A8: ■ 할 일 — 선정일 2026-06-30 에서 5거래일 앞으로 세어 자료마감일을 구하십시오.
A10: 달력 — 선정일 부근 (공통 개장일만 추린 것이 아니라 원본 그대로입니다)
B11: 날짜 | C11: 한국 개장 | D11: 미국 개장 | E11: 공통 개장일? | F11: 며칠 전? | G11: 메모
A12: 1 | B12: 2026-06-15 | C12: O | D12: O | E12: =IF(AND(C12="O",D12="O"),1,0) -> 1 | F12: {=IF(E12=0,"",SUMPRODUCT(($B$12:$B$23>B12)*($B$12:$B$23<=$B$23)*$E$12:$E$23))} -> 10
A13: 2 | B13: 2026-06-16 | C13: O | D13: O | E13: =IF(AND(C13="O",D13="O"),1,0) -> 1 | F13: {=IF(E13=0,"",SUMPRODUCT(($B$12:$B$23>B13)*($B$12:$B$23<=$B$23)*$E$12:$E$23))} -> 9
A14: 3 | B14: 2026-06-17 | C14: O | D14: O | E14: =IF(AND(C14="O",D14="O"),1,0) -> 1 | F14: {=IF(E14=0,"",SUMPRODUCT(($B$12:$B$23>B14)*($B$12:$B$23<=$B$23)*$E$12:$E$23))} -> 8
A15: 4 | B15: 2026-06-18 | C15: O | D15: O | E15: =IF(AND(C15="O",D15="O"),1,0) -> 1 | F15: {=IF(E15=0,"",SUMPRODUCT(($B$12:$B$23>B15)*($B$12:$B$23<=$B$23)*$E$12:$E$23))} -> 7
A16: 5 | B16: 2026-06-19 | C16: O | D16: - | E16: =IF(AND(C16="O",D16="O"),1,0) -> 0 | F16: {=IF(E16=0,"",SUMPRODUCT(($B$12:$B$23>B16)*($B$12:$B$23<=$B$23)*$E$12:$E$23))}
A17: 6 | B17: 2026-06-22 | C17: O | D17: O | E17: =IF(AND(C17="O",D17="O"),1,0) -> 1 | F17: {=IF(E17=0,"",SUMPRODUCT(($B$12:$B$23>B17)*($B$12:$B$23<=$B$23)*$E$12:$E$23))} -> 6
A18: 7 | B18: 2026-06-23 | C18: O | D18: O | E18: =IF(AND(C18="O",D18="O"),1,0) -> 1 | F18: {=IF(E18=0,"",SUMPRODUCT(($B$12:$B$23>B18)*($B$12:$B$23<=$B$23)*$E$12:$E$23))} -> 5
A19: 8 | B19: 2026-06-24 | C19: O | D19: O | E19: =IF(AND(C19="O",D19="O"),1,0) -> 1 | F19: {=IF(E19=0,"",SUMPRODUCT(($B$12:$B$23>B19)*($B$12:$B$23<=$B$23)*$E$12:$E$23))} -> 4
A20: 9 | B20: 2026-06-25 | C20: O | D20: O | E20: =IF(AND(C20="O",D20="O"),1,0) -> 1 | F20: {=IF(E20=0,"",SUMPRODUCT(($B$12:$B$23>B20)*($B$12:$B$23<=$B$23)*$E$12:$E$23))} -> 3
A21: 10 | B21: 2026-06-26 | C21: O | D21: O | E21: =IF(AND(C21="O",D21="O"),1,0) -> 1 | F21: {=IF(E21=0,"",SUMPRODUCT(($B$12:$B$23>B21)*($B$12:$B$23<=$B$23)*$E$12:$E$23))} -> 2
A22: 11 | B22: 2026-06-29 | C22: O | D22: O | E22: =IF(AND(C22="O",D22="O"),1,0) -> 1 | F22: {=IF(E22=0,"",SUMPRODUCT(($B$12:$B$23>B22)*($B$12:$B$23<=$B$23)*$E$12:$E$23))} -> 1
A23: 12 | B23: 2026-06-30 | C23: O | D23: O | E23: =IF(AND(C23="O",D23="O"),1,0) -> 1 | F23: {=IF(E23=0,"",SUMPRODUCT(($B$12:$B$23>B23)*($B$12:$B$23<=$B$23)*$E$12:$E$23))} -> 0
A25: 답
A26: 자료마감일 | B26: 2026-06-23 | D26: ← 이 값을 09 대조표로 옮깁니다
A28: ■ 틀리기 쉬운 곳
A29: 선정일을 1거래일 전으로 세면 하루 밀립니다. 선정일 다음이 아니라 그 앞이 1거래일 전입니다.
A30: 한쪽 시장만 열린 날을 세면 결과가 달라집니다. 실제로 이 구간에 그런 날이 있는지 확인해 보십시오.
A31: ⑧ 달력 잠정 + 축 구분 | 자료마감일(data_cutoff_date) = 선정일 이전 제5거래일, 거래일은 한·미 공통 개장일 기준 역산(근거: 회차당 단일 t* 스키마 정합, 효력발생일과 달력축 대칭). 검토 대안(시장별 역산)은 마감일 이원화로 미채택. 축 구분 명문화: 공통 거래일 축 = 자료마감·선정·효력발생 / 시장별 개장일 축 = ADTV90 90거래일·주별 관측. 정식 확정은 #30 적용시험 후(확인 항목: 회차별 공통 제5거래일, 시장별과의 날짜 차이, 기준별 이용가능률, 신규 HOLD 자료, 영향 종목·회차) |

Sheet 01 검산지도
A1: 무엇을 어떤 순서로 검산하는가
A2: 각 시트는 앞 시트의 결과를 이어받는다. 순서대로 진행하십시오.
A4: 시트 | B4: 검산 대상 | C4: 사람이 하는 일 | D4: 근거 조항 | E4: 왜 이걸 고르는가
A5: 02 | B5: 자료마감일 | C5: 선정일에서 공통 개장일 5거래일을 역산 | D5: 룰북 §5.2 · D-13 ⑧ | E5: 미래 정보 차단(PIT)의 출발점. 여기가 틀리면 전부 틀린다.
A6: 03 | B6: 일별 거래대금 | C6: 미국 종목의 종가×거래량 재구성 | D6: 룰북 제59조 · D-13 ② | E6: 한국은 거래소가 주고 미국은 우리가 만든다. 만드는 쪽을 검산한다.
A7: 04 | B7: ADTV90 | C7: 90개장일 평균. 정지일은 0으로 넣고 분모는 90 | D7: 룰북 §8.1 · D-13 ① | E7: 결측과 무거래를 같은 0으로 합치지 않는지 확인한다.
A8: 05 | B8: P10 · 편입판정 | C8: 8개 값을 정렬하고 선형보간으로 10퍼센타일 | D8: 룰북 §8.1 · §9 | E8: 경계사례가 실제로 갈리는 지점. 구조 문제도 여기서 보인다.
A9: 06 | B9: 목표비중 | C9: 3테마×2지역 6셀에 1/6씩, 셀 안은 균등 | D9: D-04 ② · D-10 ①② | E9: 합이 정확히 1이 되는지, 셀 집중도가 어떻게 되는지.
A10: 07 | B10: 지수 레벨 | C10: 기준일 대비 가중 수익률 합 | D10: 룰북 §13 · D-08 | E10: 최종 산출물. 여기까지 맞으면 파이프라인 전체가 맞다.
A11: 08 | B11: 분할 효과 | C11: 010120을 5:1 반영했을 때와 아닐 때의 차이 | D11: 데이터사전 4.1 · D-07 | E11: 성과 숫자가 왜 6.66%p 틀렸는지 직접 확인한다.
A13: ■ 표본을 이렇게 고른 이유 (룰북 §18.2 — 경계사례를 포함할 것)
A14: ADTV90 대상 KTOS: 미국 종목이라 거래대금을 우리가 재구성한다. 그리고 분포의 최솟값이라 편입 판정이 실제로 갈린다.
A15: 기업행사 010120: 파일럿 구간의 유일한 기업행사이고, 거래정지 3일과 분할이 겹쳐 있다.
A16: 회차 2026-06-30: 3/31 회차는 전 종목이 여유롭게 통과해 경계가 없다. 6/30이 검산 가치가 있다.

Sheet 03-04 거래대금·ADTV90
A1: KTOS 의 ADTV90 — 90개장일 평균 거래대금
A2: 룰북 제59조(거래대금 원천) · §8.1(ADTV90) · D-13 ①(정지일 0 반영)
A4: ■ 규칙 두 가지
A5: ① 거래대금: 한국은 거래소가 제공한 값을 그대로 씁니다. 미국은 제공값이 없어 종가 × 거래량으로 재구성합니다.
A6: KTOS는 미국 종목이므로 재구성 대상입니다. D열을 직접 계산하십시오.
A7: ② 평균: 관측창은 자료마감일부터 뒤로 90 개장일입니다. 거래정지일은 0으로 넣고 분모에서 빼지 않습니다(분모 90).
A8: 결측(자료를 못 구한 날)은 다릅니다. 결측은 분모에서 뺍니다. 둘을 같은 0으로 합치면 안 됩니다.
A10: 원자료 — 2026-02-12 ~ 2026-06-23 (미국 개장일 90일)
B11: 날짜 | C11: 종가(USD) | D11: 거래량(주) | E11: 거래대금(직접 계산) | F11: 상태코드 | G11: 메모
A12: 1 | B12: 2026-02-12 | C12: 87.05 | D12: 2276600 | E12: =C12*D12 -> 198178030 | F12: TRADED
A13: 2 | B13: 2026-02-13 | C13: 89.06 | D13: 1769100 | E13: =C13*D13 -> 157556046 | F13: TRADED
A14: 3 | B14: 2026-02-17 | C14: 91.97 | D14: 2405800 | E14: =C14*D14 -> 221261426 | F14: TRADED
A15: 4 | B15: 2026-02-18 | C15: 97.21 | D15: 3657600 | E15: =C15*D15 -> 355555296 | F15: TRADED
A16: 5 | B16: 2026-02-19 | C16: 105.67 | D16: 5176800 | E16: =C16*D16 -> 547032456 | F16: TRADED
A17: 6 | B17: 2026-02-20 | C17: 96.08 | D17: 4631600 | E17: =C17*D17 -> 445004128 | F17: TRADED
A18: 7 | B18: 2026-02-23 | C18: 94.31 | D18: 3365100 | E18: =C18*D18 -> 317362581 | F18: TRADED
A19: 8 | B19: 2026-02-24 | C19: 90.68 | D19: 6008700 | E19: =C19*D19 -> 544868916 | F19: TRADED
A20: 9 | B20: 2026-02-25 | C20: 88.23 | D20: 2349900 | E20: =C20*D20 -> 207331677 | F20: TRADED
A21: 10 | B21: 2026-02-26 | C21: 92.14 | D21: 2605000 | E21: =C21*D21 -> 240024700 | F21: TRADED
A22: 11 | B22: 2026-02-27 | C22: 86.18 | D22: 13317900 | E22: =C22*D22 -> 1147736622 | F22: TRADED
A23: 12 | B23: 2026-03-02 | C23: 90.72 | D23: 18913800 | E23: =C23*D23 -> 1715859936 | F23: TRADED
... A101: 90 | B101: 2026-06-23 | C101: 50.8 | D101: 3683300 | E101: =C101*D101 -> 187111640 | F101: TRADED
A103: 집계
A104: 관측 개장일수 (분모가 되는 수) | B104: =COUNT(A12:A101) -> 90 | D104: 위 표의 행 수
A105: 그중 거래정지일 수 | B105: =COUNTIF(F12:F101,"TRADING_HALT") -> 0 | D105: 상태코드가 TRADING_HALT 인 날
A106: 그중 결측일 수 | B106: =COUNTIF(F12:F101,"DATA_MISSING") -> 0 | D106: 자료 자체가 없는 날 — 분모에서 뺄 대상
A107: 거래대금 합계 | B107: =SUM(E12:E101) -> 28363930310 | D107: E12:E101 의 합
A108: ADTV90 = 합계 ÷ 분모 | B108: =B107/(B104-B106) -> 3.1515478e+08 | D108: 분모를 무엇으로 잡았는지 메모에 적으십시오
A110: ■ 스스로 점검할 것
A111: 분모를 90으로 했습니까, 아니면 정지일을 뺀 수로 했습니까? 규칙은 90입니다. 왜 그런지 설명할 수 있습니까?
A112: 만약 정지일을 분모에서 뺐다면 ADTV90이 커집니다. 편입 판정이 뒤집힐 수 있습니다. 다음 시트에서 확인됩니다.

Sheet 05 P10·편입판정
A1: P10 하한과 편입 판정
A2: 룰북 §8.1(분포·하한) · §9(편입) · 선형보간
A4: ■ 규칙
A5: 같은 시장 안에서 ADTV90이 산출된 종목들을 모아 10퍼센타일을 구합니다. 그보다 낮으면 유동성 미달로 제외합니다.
A6: 시즈닝(상장 후 유효관측 90일)을 못 채운 종목은 ADTV90 자체가 산출되지 않아 분포에서 빠집니다.
A8: ■ 선형보간으로 퍼센타일 구하는 법
A9: 값을 작은 순으로 정렬하고 0부터 번호를 붙입니다. 위치 h = (n − 1) × (백분위 ÷ 100).
A10: h가 정수가 아니면 아래위 두 값 사이를 비례로 나눕니다. 값 = x[내림] + (h − 내림) × (x[올림] − x[내림])
A12: ■ 할 일 — 아래 미국 종목 분포에서 P10을 구하고 KTOS의 편입 여부를 판정하십시오.
A13: KTOS 칸은 비어 있습니다. 앞 시트에서 직접 계산한 값을 넣으십시오.
A15: 미국 시장 ADTV90 분포 — 검산 대상 종목만 비워 두었습니다
B16: 종목 | C16: ADTV90 (USD) | D16: 시즈닝 | E16: 분포 포함? | F16: 정렬 후 순번 | G16: 메모
B17: ALAB | C17: 1.2523214e+09 | D17: SEASONED | E17: =IF(D17="SEASONED","포함","제외") -> 포함 | F17: =IF(E17="포함",RANK(C17,$C$17:$C$25,1),"") -> 4
B18: ANET | C18: 1.3141537e+09 | D18: SEASONED | E18: =IF(D18="SEASONED","포함","제외") -> 포함 | F18: =IF(E18="포함",RANK(C18,$C$17:$C$25,1),"") -> 5
B19: APH | C19: 1.3426972e+09 | D19: SEASONED | E19: =IF(D19="SEASONED","포함","제외") -> 포함 | F19: =IF(E19="포함",RANK(C19,$C$17:$C$25,1),"") -> 7
B20: ATI | C20: 3.1762617e+08 | D20: SEASONED | E20: =IF(D20="SEASONED","포함","제외") -> 포함 | F20: =IF(E20="포함",RANK(C20,$C$17:$C$25,1),"") -> 2
B21: ETN | C21: 1.0163644e+09 | D21: SEASONED | E21: =IF(D21="SEASONED","포함","제외") -> 포함 | F21: =IF(E21="포함",RANK(C21,$C$17:$C$25,1),"") -> 3
B22: GEV | C22: 2.5086036e+09 | D22: SEASONED | E22: =IF(D22="SEASONED","포함","제외") -> 포함 | F22: =IF(E22="포함",RANK(C22,$C$17:$C$25,1),"") -> 8
B23: KTOS | C23: ='03-04 거래대금·ADTV90'!B108 -> 3.1515478e+08 | D23: SEASONED | E23: =IF(D23="SEASONED","포함","제외") -> 포함 | F23: =IF(E23="포함",RANK(C23,$C$17:$C$25,1),"") -> 1 | G23: ← 03-04 시트에서 직접 계산한 값
B24: TER | C24: 1.3224047e+09 | D24: SEASONED | E24: =IF(D24="SEASONED","포함","제외") -> 포함 | F24: =IF(E24="포함",RANK(C24,$C$17:$C$25,1),"") -> 6
B25: SPCX | C25: (산출 안 됨) | D25: SEASONING_INCOMPLETE | E25: =IF(D25="SEASONED","포함","제외") -> 제외 | F25: =IF(E25="포함",RANK(C25,$C$17:$C$25,1),"") | G25: 분포에 넣을지 판단하십시오
A27: 계산
A28: 분포에 들어간 종목 수 n | B28: =COUNT(C17:C24) -> 8 | D28: ADTV90이 산출된 종목만
A29: 보간 위치 h = (n−1) × 0.10 | B29: =(B28-1)*0.1 -> 0.7 | D29: 소수로 나옵니다
A30: h 아래 정수 위치의 값 | B30: =SMALL($C$17:$C$24,INT(B29)+1) -> 3.1515478e+08 | D30: 정렬 후 x[내림]
A31: h 위 정수 위치의 값 | B31: =SMALL($C$17:$C$24,INT(B29)+2) -> 3.1762617e+08 | D31: 정렬 후 x[올림]
A32: P10 하한 | B32: =B30+(B29-INT(B29))*(B31-B30) -> 3.1688475e+08 | D32: 위 보간식을 적용
A33: KTOS 편입 여부 | B33: =IF(C23>=B32,"편입","제외") -> 제외 | D33: P10 이상이면 편입, 미만이면 제외
A34: KTOS의 P10 대비 차이(%) | B34: =(C23/B32-1)*100 -> -0.54593122 | D34: (ADTV90 ÷ P10 − 1) × 100
A35: P10 미만인 종목 수 | B35: =COUNTIF($C$17:$C$24,"<"&B32) -> 1 | D35: 몇 개나 떨어졌습니까?
A37: ■ 다 구한 뒤에 생각해 볼 것 — 이것이 발표에서 쓸 내용입니다
A38: h를 계산해 보면 0과 1 사이입니다. 그러면 P10은 항상 '가장 작은 값'과 '두 번째로 작은 값' 사이에 놓입니다.
A39: 즉 P10 미만인 종목은 언제나 정확히 한 개입니다. 그 종목의 거래대금이 크든 작든 상관없습니다.
A40: → 지금 규칙은 '유동성이 일정 수준 미만이면 제외'가 아니라 '가장 낮은 하나를 제외'로 작동하고 있습니다.
A41: → 종목 수가 몇 개가 되어야 두 개 이상 떨어질 수 있습니까? h ≥ 1 이 되는 n을 구해 보십시오.값: 2026-06-23 근거: 결정로그 323행 D-13 ⑧ — "선정일 이전 제5거래일, 한·미 공통 개장일 기준 역산" "이전"이 선정일을 제외하므로 6/29부터 1,2,3,4,5 를 세어 6/23. 한계: 조문이 기산점(선정일을 0으로 볼지)을 명시하지 않았다. "이전"이라는 전치사로 추론했다. 조문 자체가 "정식 확정은 #30 적용시험 후"로 잠정 표기돼 있다. 제안: 데이터사전에 "기산점 = 선정일 당일 제외" 를 명문화할 것. 또는 조문을 "선정일 직전 거래일을 제1거래일로 하여 역산한 제5거래일" 로 정정.
A43: 두 개 이상 떨어지려면 필요한 최소 n | B43: =CEILING(1/0.1,1)+1 -> 11

Sheet 06 목표비중
A1: 6셀 구조와 목표비중
A2: D-04 ②(테마 1:1:1) · D-10 ①(지역 50:50) · D-10 ②(6셀 각 1/6)
A4: ■ 규칙
A5: 테마 3개(우주방산·AI로보틱스·에너지전력)에 각각 1/3, 지역 2개(한국·미국)에 각각 1/2.
A6: 두 조건을 함께 만족하도록 3×2 = 6개 셀에 각 1/6씩 배분합니다.
A7: 셀 안에서는 편입된 종목끼리 균등하게 나눕니다. 셀에 1종목뿐이면 그 종목이 1/6을 전부 갖습니다.
A9: ■ 할 일 — 각 셀의 편입 종목 수를 세고, 종목별 목표비중을 계산하십시오.
A11: ■ 주의 — 여기서 쓰는 회차는 05 시트와 다릅니다. 헷갈리기 쉬운 지점입니다.
A12: 05 시트는 2026-06-30 회차의 편입 판정이었습니다. 그 결과는 '다음 구간'에 적용될 것입니다.
A13: 지금 지수 산출구간(2026-04-01~06-30)에 실제로 적용된 것은 2026-03-31 회차 선정분입니다.
A14: 그래서 이 시트는 3/31 회차를 씁니다. 07 시트의 지수 계산도 이 비중을 씁니다.
A15: → 선정일과 적용일은 다릅니다. 6/30 선정분은 적용일이 이 구간 밖이라 지수에 들어가지 않았습니다.
... A18: 셀별 집계
B19: 셀 | C19: 테마 | D19: 지역 | E19: 셀 목표비중 | F19: 편입 종목수 | G19: 종목당 비중 | H19: 메모
B20: KR_AI_ROBOTICS | C20: AI_ROBOTICS | D20: KR | E20: 0.16666667 | F20: =COUNTIF($E$30:$E$44,B20) -> 2 | G20: =IF(F20=0,"",E20/F20) -> 0.083333333
B21: KR_ENERGY_POWER | C21: ENERGY_POWER | D21: KR | E21: 0.16666667 | F21: =COUNTIF($E$30:$E$44,B21) -> 3 | G21: =IF(F21=0,"",E21/F21) -> 0.055555556
B22: KR_SPACE_DEFENSE | C22: SPACE_DEFENSE | D22: KR | E22: 0.16666667 | F22: =COUNTIF($E$30:$E$44,B22) -> 3 | G22: =IF(F22=0,"",E22/F22) -> 0.055555556
B23: US_AI_ROBOTICS | C23: AI_ROBOTICS | D23: US | E23: 0.16666667 | F23: =COUNTIF($E$30:$E$44,B23) -> 3 | G23: =IF(F23=0,"",E23/F23) -> 0.055555556
B24: US_ENERGY_POWER | C24: ENERGY_POWER | D24: US | E24: 0.16666667 | F24: =COUNTIF($E$30:$E$44,B24) -> 3 | G24: =IF(F24=0,"",E24/F24) -> 0.055555556
B25: US_SPACE_DEFENSE | C25: SPACE_DEFENSE | D25: US | E25: 0.16666667 | F25: =COUNTIF($E$30:$E$44,B25) -> 1 | G25: =IF(F25=0,"",E25/F25) -> 0.16666667
D26: 합계 | E26: =SUM(E20:E25) -> 1 | H26: 정확히 1.000000 이어야 합니다
A28: 종목별 목표비중 — 편입 종목 전체
B29: 종목 | C29: 지역 | D29: 테마 | E29: 셀 | F29: 목표비중 | H29: 메모
B30: 064400 | C30: KR | D30: AI_ROBOTICS | E30: KR_AI_ROBOTICS | F30: =VLOOKUP(E30,$B$20:$G$25,6,FALSE) -> 0.083333333
B31: 307950 | C31: KR | D31: AI_ROBOTICS | E31: KR_AI_ROBOTICS | F31: =VLOOKUP(E31,$B$20:$G$25,6,FALSE) -> 0.083333333
B32: 010120 | C32: KR | D32: ENERGY_POWER | E32: KR_ENERGY_POWER | F32: =VLOOKUP(E32,$B$20:$G$25,6,FALSE) -> 0.055555556
B33: 267260 | C33: KR | D33: ENERGY_POWER | E33: KR_ENERGY_POWER | F33: =VLOOKUP(E33,$B$20:$G$25,6,FALSE) -> 0.055555556
B34: 298040 | C34: KR | D34: ENERGY_POWER | E34: KR_ENERGY_POWER | F34: =VLOOKUP(E34,$B$20:$G$25,6,FALSE) -> 0.055555556
B35: 012450 | C35: KR | D35: SPACE_DEFENSE | E35: KR_SPACE_DEFENSE | F35: =VLOOKUP(E35,$B$20:$G$25,6,FALSE) -> 0.055555556
B36: 064350 | C36: KR | D36: SPACE_DEFENSE | E36: KR_SPACE_DEFENSE | F36: =VLOOKUP(E36,$B$20:$G$25,6,FALSE) -> 0.055555556
B37: 079550 | C37: KR | D37: SPACE_DEFENSE | E37: KR_SPACE_DEFENSE | F37: =VLOOKUP(E37,$B$20:$G$25,6,FALSE) -> 0.055555556
B38: ALAB | C38: US | D38: AI_ROBOTICS | E38: US_AI_ROBOTICS | F38: =VLOOKUP(E38,$B$20:$G$25,6,FALSE) -> 0.055555556
B39: ANET | C39: US | D39: AI_ROBOTICS | E39: US_AI_ROBOTICS | F39: =VLOOKUP(E39,$B$20:$G$25,6,FALSE) -> 0.055555556
B40: TER | C40: US | D40: AI_ROBOTICS | E40: US_AI_ROBOTICS | F40: =VLOOKUP(E40,$B$20:$G$25,6,FALSE) -> 0.055555556
B41: APH | C41: US | D41: ENERGY_POWER | E41: US_ENERGY_POWER | F41: =VLOOKUP(E41,$B$20:$G$25,6,FALSE) -> 0.055555556
... B44: KTOS | C44: US | D44: SPACE_DEFENSE | E44: US_SPACE_DEFENSE | F44: =VLOOKUP(E44,$B$20:$G$25,6,FALSE) -> 0.16666667
E45: 합계 | F45: =SUM(F30:F44) -> 1
A47: ■ 다 구한 뒤에 생각해 볼 것
A48: 가장 큰 비중을 가진 종목은 몇 퍼센트입니까? 다른 종목의 몇 배입니까?
A49: 그 셀에 종목이 몇 개 있습니까? 그 종목이 다음 회차에 빠지면 그 셀은 어떻게 됩니까?
...

Sheet 07 지수레벨
A1: 지수 레벨 — 2026-04-07
A2: 룰북 §13 · D-08 · 기준일 2026-04-01 = 1,000 · 원화 · 무헤지
A4: ■ 규칙
A5: 구간 시작일 가격 대비 현재 가격의 비율을 종목마다 구하고, 목표비중을 곱해 모두 더합니다.
A6: 거기에 기준값 1,000을 곱하면 지수 레벨입니다.
A7: 미국 종목은 그날의 환율로 원화로 바꾼 뒤에 비율을 계산합니다. 환율도 날마다 다릅니다.
A9: 지수 = 1000 × Σ ( 목표비중 × 당일가격(원) ÷ 기준일가격(원) )
A11: ■ 할 일 — 2026-04-07 의 지수 레벨을 구하십시오. (분할 이전 날짜라 기업행사 문제는 없습니다)
A12: 목표비중(D열)은 주어져 있지 않습니다. 06 시트에서 직접 계산한 값을 옮겨 적으십시오.
A14: 환율 (ECOS 매매기준율, 평가일 당일 적용)
A15: 기준일 2026-04-01 | C15: 1530.5 | E15: 검산일 2026-04-07 | G15: 1507.2
B17: 종목 | C17: 지역 | D17: 목표비중 | E17: 기준일 종가 | F17: 검산일 종가 | G17: 기준일 가격(원) | H17: 검산일 가격(원) | I17: 가격비 | J17: 비중×가격비
B18: 010120 | C18: KR | D18: =VLOOKUP($B18,'06 목표비중'!$B$30:$F$44,5,FALSE) -> 0.055555556 | E18: 794000 | F18: 788000 | G18: =IF($C18="KR",E18,E18*$C$15) -> 794000 | H18: =IF($C18="KR",F18,F18*$G$15) -> 788000 | I18: =H18/G18 -> 0.99244332 | J18: =$D18*I18 -> 0.05513574
B19: 012450 | C19: KR | D19: =VLOOKUP($B19,'06 목표비중'!$B$30:$F$44,5,FALSE) -> 0.055555556 | E19: 1333000 | F19: 1537000 | G19: =IF($C19="KR",E19,E19*$C$15) -> 1333000 | H19: =IF($C19="KR",F19,F19*$G$15) -> 1537000 | I19: =H19/G19 -> 1.1530383 | J19: =$D19*I19 -> 0.064057681
B20: 064350 | C20: KR | D20: =VLOOKUP($B20,'06 목표비중'!$B$30:$F$44,5,FALSE) -> 0.055555556 | E20: 188800 | F20: 211000 | G20: =IF($C20="KR",E20,E20*$C$15) -> 188800 | H20: =IF($C20="KR",F20,F20*$G$15) -> 211000 | I20: =H20/G20 -> 1.1175847 | J20: =$D20*I20 -> 0.062088041
B21: 064400 | C21: KR | D21: =VLOOKUP($B21,'06 목표비중'!$B$30:$F$44,5,FALSE) -> 0.083333333 | E21: 59500 | F21: 57100 | G21: =IF($C21="KR",E21,E21*$C$15) -> 59500 | H21: =IF($C21="KR",F21,F21*$G$15) -> 57100 | I21: =H21/G21 -> 0.95966387 | J21: =$D21*I21 -> 0.079971989
B22: 079550 | C22: KR | D22: =VLOOKUP($B22,'06 목표비중'!$B$30:$F$44,5,FALSE) -> 0.055555556 | E22: 794000 | F22: 827000 | G22: =IF($C22="KR",E22,E22*$C$15) -> 794000 | H22: =IF($C22="KR",F22,F22*$G$15) -> 827000 | I22: =H22/G22 -> 1.0415617 | J22: =$D22*I22 -> 0.05786454
B23: 267260 | C23: KR | D23: =VLOOKUP($B23,'06 목표비중'!$B$30:$F$44,5,FALSE) -> 0.055555556 | E23: 902000 | F23: 891000 | G23: =IF($C23="KR",E23,E23*$C$15) -> 902000 | H23: =IF($C23="KR",F23,F23*$G$15) -> 891000 | I23: =H23/G23 -> 0.98780488 | J23: =$D23*I23 -> 0.054878049
B24: 298040 | C24: KR | D24: =VLOOKUP($B24,'06 목표비중'!$B$30:$F$44,5,FALSE) -> 0.055555556 | E24: 2653000 | F24: 2610000 | G24: =IF($C24="KR",E24,E24*$C$15) -> 2653000 | H24: =IF($C24="KR",F24,F24*$G$15) -> 2610000 | I24: =H24/G24 -> 0.98379193 | J24: =$D24*I24 -> 0.054655107
B25: 307950 | C25: KR | D25: =VLOOKUP($B25,'06 목표비중'!$B$30:$F$44,5,FALSE) -> 0.083333333 | E25: 391000 | F25: 370000 | G25: =IF($C25="KR",E25,E25*$C$15) -> 391000 | H25: =IF($C25="KR",F25,F25*$G$15) -> 370000 | I25: =H25/G25 -> 0.94629156 | J25: =$D25*I25 -> 0.07885763
B26: ALAB | C26: US | D26: =VLOOKUP($B26,'06 목표비중'!$B$30:$F$44,5,FALSE) -> 0.055555556 | E26: 106.33 | F26: 118.99 | G26: =IF($C26="KR",E26,E26*$C$15) -> 162738.07 | H26: =IF($C26="KR",F26,F26*$G$15) -> 179341.73 | I26: =H26/G26 -> 1.1020269 | J26: =$D26*I26 -> 0.061223718
B27: ANET | C27: US | D27: =VLOOKUP($B27,'06 목표비중'!$B$30:$F$44,5,FALSE) -> 0.055555556 | E27: 124.85 | F27: 133.64 | G27: =IF($C27="KR",E27,E27*$C$15) -> 191082.92 | H27: =IF($C27="KR",F27,F27*$G$15) -> 201422.21 | I27: =H27/G27 -> 1.0541089 | J27: =$D27*I27 -> 0.058561604
B28: APH | C28: US | D28: =VLOOKUP($B28,'06 목표비중'!$B$30:$F$44,5,FALSE) -> 0.055555556 | E28: 127.7 | F28: 128.38 | G28: =IF($C28="KR",E28,E28*$C$15) -> 195444.85 | H28: =IF($C28="KR",F28,F28*$G$15) -> 193494.34 | I28: =H28/G28 -> 0.99002013 | J28: =$D28*I28 -> 0.055001118
B29: ETN | C29: US | D29: =VLOOKUP($B29,'06 목표비중'!$B$30:$F$44,5,FALSE) -> 0.055555556 | E29: 365.56 | F29: 368.85 | G29: =IF($C29="KR",E29,E29*$C$15) -> 559489.58 | H29: =IF($C29="KR",F29,F29*$G$15) -> 555930.72 | I29: =H29/G29 -> 0.9936391 | J29: =$D29*I29 -> 0.055202172
... B32: TER | C32: US | D32: =VLOOKUP($B32,'06 목표비중'!$B$30:$F$44,5,FALSE) -> 0.055555556 | E32: 312.2 | F32: 320.48 | G32: =IF($C32="KR",E32,E32*$C$15) -> 477822.1 | H32: =IF($C32="KR",F32,F32*$G$15) -> 483027.46 | I32: =H32/G32 -> 1.0108939 | J32: =$D32*I32 -> 0.056160773
I33: 합계 | J33: =SUM(J18:J32) -> 1.0238016
A35: 답
A36: 2026-04-07 지수 레벨 = 1000 × 합계 | D36: =1000*J33 -> 1023.8016
A38: ■ 틀리기 쉬운 곳
A39: 한국 종목에 환율을 곱하면 안 됩니다. 이미 원화입니다.
A40: 미국 종목은 기준일과 검산일에 서로 다른 환율을 씁니다. 같은 환율을 쓰면 환율 변동분이 사라집니다.
A41: 비중은 소수점 아래가 깁니다(1/18 = 0.055556). 반올림하면 합계가 어긋납니다.

Sheet 08 분할효과
A1: 010120 액면분할 5:1 — 반영했을 때와 안 했을 때
A2: 데이터사전 4.1 · D-07 · DART 20260205800493 / 20260205800571(정정)
A4: ■ 무슨 일이 있었나
A5: 2026-02-05 이사회에서 1주를 5주로 쪼개기로 결정했습니다(액면가 5,000원 → 1,000원).
A6: 2026-04-08~10 사흘간 거래가 정지됐고 04-13에 재개됐습니다.
A7: 재산은 그대로인데 주가 숫자만 1/5이 됩니다. 이것을 반영하지 않으면 주가가 폭락한 것처럼 보입니다.
A9: ■ 조정 방법 (데이터사전 4.1)
A10: 효력일(2026-04-13) '이전' 가격을 분할비율 5로 나눕니다. 이후 가격은 그대로 둡니다.
A11: 거래정지 기간의 가격도 분할 전 기준이므로 함께 나눕니다.
A13: ■ 할 일 — 아래 두 열을 채우고 04-13의 수익률을 두 가지로 구해 비교하십시오.
B15: 날짜 | C15: 원종가 | D15: 상태코드 | E15: 분할조정 종가 | F15: 전일대비 수익률 | G15: 메모
B16: 2026-04-06 | C16: 799000 | D16: TRADED | E16: =IF($B16<$B$21,C16/5,C16) -> 159800 | F16: =""
B17: 2026-04-07 | C17: 788000 | D17: TRADED | E17: =IF($B17<$B$21,C17/5,C17) -> 157600 | F17: =E17/E16-1 -> -0.013767209
B18: 2026-04-08 | C18: 788000 | D18: TRADING_HALT | E18: =IF($B18<$B$21,C18/5,C18) -> 157600 | F18: =E18/E17-1 -> 0
B19: 2026-04-09 | C19: 788000 | D19: TRADING_HALT | E19: =IF($B19<$B$21,C19/5,C19) -> 157600 | F19: =E19/E18-1 -> 0
B20: 2026-04-10 | C20: 788000 | D20: TRADING_HALT | E20: =IF($B20<$B$21,C20/5,C20) -> 157600 | F20: =E20/E19-1 -> 0
B21: 2026-04-13 | C21: 179200 | D21: TRADED | E21: =IF($B21<$B$21,C21/5,C21) -> 179200 | F21: =E21/E20-1 -> 0.13705584
B22: 2026-04-14 | C22: 185600 | D22: TRADED | E22: =IF($B22<$B$21,C22/5,C22) -> 185600 | F22: =E22/E21-1 -> 0.035714286
B23: 2026-04-15 | C23: 186800 | D23: TRADED | E23: =IF($B23<$B$21,C23/5,C23) -> 186800 | F23: =E23/E22-1 -> 0.0064655172
B24: 2026-04-16 | C24: 188600 | D24: TRADED | E24: =IF($B24<$B$21,C24/5,C24) -> 188600 | F24: =E24/E23-1 -> 0.0096359743
A26: 04-13 수익률 비교
A27: ① 조정 안 했을 때 (원종가 그대로) | C27: =C21/C17-1 -> -0.77258883 | D27: 179,200 ÷ 788,000 − 1
A28: ② 조정 했을 때 | C28: =C21/E17-1 -> 0.13705584 | D28: 179,200 ÷ (788,000÷5) − 1
A29: ③ 차이 (① − ②) | C29: =C27-C28 -> -0.90964467 | D29: 이만큼이 실재하지 않는 하락입니다
A30: ④ 지수에 준 영향 = ③ × 010120 목표비중 | C30: =C29*VLOOKUP("010120",'06 목표비중'!$B$30:$F$44,5,FALSE) -> -0.050535815 | D30: 비중은 06 시트에서
A32: ■ 자기 점검 — 여기가 가장 중요합니다
A33: 조정한 뒤 04-13의 수익률이 0% 가 나왔다면 두 번 나눈 것입니다(과보정). 다시 확인하십시오.
A34: 올바르게 조정하면 04-13은 '플러스' 수익률이 나옵니다. 분할 기준가보다 높게 거래가 재개됐기 때문입니다.
A35: → 실제 시장이 분할을 호재로 봤다는 뜻이고, 그것이 진짜 정보입니다. 조정 전 숫자는 그것을 지워버립니다.
A37: ■ 조정 경계일을 04-10(효력발생일)으로 잡으면 어떻게 됩니까?
A38: 공시에는 신주 효력발생일이 04-10, 신주권상장일이 04-13으로 따로 적혀 있습니다.
A39: 04-10을 경계로 잡으면 정지 기간의 가격이 조정되지 않아 왜곡이 04-13에서 04-10으로 자리만 옮깁니다.
A40: → 가격 계열에서는 거래가 실제로 재개된 04-13이 경계입니다. 직접 확인해 보십시오.

Sheet 09 대조표
A1: 수기값 · 코드값 대조표
A2: 노란 칸을 전부 채우고 저장한 뒤에 J5_코드값_봉인.xlsx 를 열어 F열을 채웁니다
A4: ■ 순서
A5: ① 앞 시트의 답 칸을 E열에 옮겨 적습니다. ② 이 파일을 저장합니다.
A6: ③ 그 다음에 봉인 파일을 열어 F열을 채웁니다. ④ G열에 일치 여부를 고릅니다.
A7: 불일치가 나오면 반드시 H열에 원인을 적습니다. 불일치를 지우지 마십시오 — 그것이 검산의 성과입니다.
B9: 시트 | C9: 검산 항목 | D9: 단위 | E9: 수기값 | F9: 코드값 | G9: 판정 | H9: 불일치 원인 / 메모
A10: A | B10: 02 | C10: 자료마감일 | D10: 날짜 | E10: ='02 자료마감일'!B26 -> 2026-06-23
A11: B | B11: 03-04 | C11: KTOS ADTV90 | D11: USD | E11: ='03-04 거래대금·ADTV90'!B108 -> 3.1515478e+08
A12: C | B12: 03-04 | C12: ADTV90 분모(개장일수) | D12: 일 | E12: ='03-04 거래대금·ADTV90'!B104-'03-04 거래대금·ADTV90'!B106 -> 90
A13: D | B13: 05 | C13: 미국 P10 하한 | D13: USD | E13: ='05 P10·편입판정'!B32 -> 3.1688475e+08
A14: E | B14: 05 | C14: KTOS 편입 여부 | D14: 편입/제외 | E14: ='05 P10·편입판정'!B33 -> 제외
A15: F | B15: 05 | C15: P10 미만 종목 수 | D15: 개 | E15: ='05 P10·편입판정'!B35 -> 1
A16: G | B16: 05 | C16: 2종목 이상 탈락에 필요한 최소 n | D16: 개 | E16: ='05 P10·편입판정'!B43 -> 11
A17: H | B17: 06 | C17: 목표비중 합계 (3/31 회차) | D17: 비율 | E17: ='06 목표비중'!F45 -> 1
A18: I | B18: 06 | C18: 최대 비중 종목의 비중 (3/31 회차) | D18: % | E18: ='06 목표비중'!B53 -> 16.666667
A19: J | B19: 07 | C19: 2026-04-07 지수 레벨 | D19: 포인트 | E19: ='07 지수레벨'!D36 -> 1023.8016
A20: K | B20: 08 | C20: 04-13 조정 전 수익률 | D20: % | E20: ='08 분할효과'!C27*100 -> -77.258883
A21: L | B21: 08 | C21: 04-13 조정 후 수익률 | D21: % | E21: ='08 분할효과'!C28*100 -> 13.705584
A23: 종합
A24: 일치 항목 수 | D24: =COUNTIF($G$10:$G$21,"일치") -> 0
A25: 불일치 항목 수 | D25: =COUNTIF($G$10:$G$21,"불일치") -> 0
A26: 검산 결론 (한 문장) | D26: =IF(COUNTA($F$10:$F$21)<12,"코드값 미입력 — 봉인 파일 개봉 후 F·G열을 채우면 결론이 자동 산출됩니다",IF(D25=0,"12개 항목 전부 일치 — 구현이 규칙대로 작동함을 수기 검산으로 확인","불일치 "&D25&"건 — H열에 원인을 기록할 것")) -> 코드값 미입력 — 봉인 파일 개봉 후 F·G열을 채우면 결론이 자동 산출됩니다

Sheet 10 발표용요약
A1: 발표용 요약 — 채우고 나면 이 시트를 그대로 쓸 수 있습니다
A2: 무엇을 검증했고 무엇이 확인됐는지 한 장으로 보여 주는 용도
A4: ■ 이 시트의 쓰임
A5: 대조표를 채운 뒤 결과를 여기에 옮기면 발표 슬라이드 한 장이 됩니다.
A6: 성과 숫자가 아니라 '우리 숫자를 어디까지 믿을 수 있는지'를 보여 주는 자료입니다.
A8: 검증 결과
B9: 검증한 것 | C9: 수기값 | D9: 코드값 | E9: 판정 | F9: 이 항목이 확인해 주는 것
A10: A | B10: 자료마감일 | C10: ='09 대조표'!E10 -> 2026-06-23 | D10: ='09 대조표'!F10 -> 0 | E10: ='09 대조표'!G10 -> 0 | F10: 미래 정보가 섞이지 않았다 (PIT)
A11: B | B11: KTOS ADTV90 | C11: ='09 대조표'!E11 -> 3.1515478e+08 | D11: ='09 대조표'!F11 -> 0 | E11: ='09 대조표'!G11 -> 0 | F11: 미국 거래대금 재구성이 제59조대로 되었다
A12: C | B12: ADTV90 분모(개장일수) | C12: ='09 대조표'!E12 -> 90 | D12: ='09 대조표'!F12 -> 0 | E12: ='09 대조표'!G12 -> 0 | F12: 정지일과 결측일을 다르게 처리했다 (R6)
A13: D | B13: 미국 P10 하한 | C13: ='09 대조표'!E13 -> 3.1688475e+08 | D13: ='09 대조표'!F13 -> 0 | E13: ='09 대조표'!G13 -> 0 | F13: 유동성 하한이 규칙대로 산출되었다
A14: E | B14: KTOS 편입 여부 | C14: ='09 대조표'!E14 -> 제외 | D14: ='09 대조표'!F14 -> 0 | E14: ='09 대조표'!G14 -> 0 | F14: 경계 종목의 판정이 임의적이지 않다
A15: F | B15: P10 미만 종목 수 | C15: ='09 대조표'!E15 -> 1 | D15: ='09 대조표'!F15 -> 0 | E15: ='09 대조표'!G15 -> 0 | F15: 지금 규칙이 매 회차 정확히 1종목을 제외한다
A16: G | B16: 2종목 이상 탈락에 필요한 최소 n | C16: ='09 대조표'!E16 -> 11 | D16: ='09 대조표'!F16 -> 0 | E16: ='09 대조표'!G16 -> 0 | F16: 그 성질이 표본 크기에서 나온 것이다
A17: H | B17: 목표비중 합계 (3/31 회차) | C17: ='09 대조표'!E17 -> 1 | D17: ='09 대조표'!F17 -> 0 | E17: ='09 대조표'!G17 -> 0 | F17: 비중 합이 정확히 1이다
A18: I | B18: 최대 비중 종목의 비중 (3/31 회차) | C18: ='09 대조표'!E18 -> 16.666667 | D18: ='09 대조표'!F18 -> 0 | E18: ='09 대조표'!G18 -> 0 | F18: 개별종목 집중도가 어느 수준인지
A19: J | B19: 2026-04-07 지수 레벨 | C19: ='09 대조표'!E19 -> 1023.8016 | D19: ='09 대조표'!F19 -> 0 | E19: ='09 대조표'!G19 -> 0 | F19: 최종 지수값이 규칙대로 산출되었다
A20: K | B20: 04-13 조정 전 수익률 | C20: ='09 대조표'!E20 -> -77.258883 | D20: ='09 대조표'!F20 -> 0 | E20: ='09 대조표'!G20 -> 0 | F20: 기업행사 미반영 시 얼마나 왜곡되는지
A21: L | B21: 04-13 조정 후 수익률 | C21: ='09 대조표'!E21 -> 13.705584 | D21: ='09 대조표'!F21 -> 0 | E21: ='09 대조표'!G21 -> 0 | F21: 조정 후 값이 실제 시장 반응과 맞는지
A23: ■ 발표에서 말할 문장 (검산 결과에 맞게 고쳐 쓰십시오)
A24: 우리는 코드가 낸 지수를 사람이 원자료부터 손으로 다시 계산해 대조했습니다.
A25: 자료마감일, 거래대금 재구성, ADTV90, 유동성 하한, 목표비중, 지수 레벨까지 12개 항목입니다.
A26: 이 과정에서 규칙 자체의 성질도 확인했습니다 — 지금의 유동성 하한은 후보군이 작아서
A27: 매 회차 가장 낮은 한 종목만 제외하는 방식으로 작동합니다. 이것은 알고 채택한 것입니다.
A29: ■ 하지 말아야 할 말
A30: '검산이 맞았으니 성과도 믿을 만하다' — 검산은 계산이 규칙대로 되었는지만 말합니다.
A31: 성과의 유의성은 표본 58일, 추적오차 33%로 통계적으로 판정할 수 없습니다. 이 둘은 다른 이야기입니다.
